Workbook

Sheet Copy of Sheet1
A4: loan name | B4: total take amt | C4: start date | D4: rest amount | E4: emi | F4: end date | G4: intrest rate
A5: icic credit card | B5: 30k | C5: 45931 | D5: 9k | E5: 8950 | F5: 46300 | G5: 18
A6: cred1 | B6: 20k | C6: 46113 | D6: 8k | E6: 2.8k | F6: 46362 | G6: 16.5
A7: slice | B7: 3.0L | C7: 46113 | D7: 1.75L | E7: 25.6k | F7: 46512 | G7: 26
A8: cred2 | B8: 1.5L | C8: 46179 | D8: 1.22L | E8: 11.3k | F8: 46605 | G8: 16.5
A9: piramal | B9: 7.L | C9: 46058 | D9: 9.55L | E9: 18.4k | F9: 47884 | G9: 18.6
A10: abba bc | B10: 2L | D10: 40k | E10: 9k | F10: 46466 | G10: 0
A11: idfc | B11: 1.3L | C11: 46147 | D11: 1.7L | E11: 5k | F11: 47289 | G11: 23
A12: mahila samiti | B12: 1.4L | C12: 4.5k intrest | D12: 1.5L | G12: 36
A13: riyasat 2k | B13: 50k | D13: 30k | E13: 2k | G13: 0
A14: riyasat 2ksha | B14: 50k | D14: 40k | E14: 2k | G14: 0
A15: riyasat 1k | B15: 20k | D15: 10k | E15: 1k | G15: 0
A16: charku1 | D16: 24k | E16: 3k | G16: 0
A17: charku2 | D17: 50k | E17: 3k | G17: 0
A18: pinki | B18: 50k | D18: 50k | E18: 50k | G18: 0
A19: jewar | B19: 35k | C19: 1k intrest | D19: 35k | E19: 35k | G19: 36
A20: jalil | B20: 2.10L | D20: 2.10L | E20: 2.10L | G20: 0
A21: door | B21: 25k | D21: 25k | G21: 0
A22: cement | D22: 50k | G22: 0
A23: kalijan | D23: 30k | G23: 0
A24: khatija | D24: 30k | G24: 0
A25: mamu | D25: 20k | G25: 0
A26: extra payment | D26: 20k | G26: 0
A27: home expenses | D27: 10k | E27: 10k | G27: 0
A28: muk loan
D31: 22.63 L

Sheet Sheet1
B2: 💳 Loan Repayment & Debt Portfolio Tracker | H2: Currency: INR (₹) • Status: Active Portfolio
B4: TOTAL OUTSTANDING BALANCE | D4: MONTHLY EMI OUTFLOW | F4: HIGHEST INTEREST RATE | H4: ACTIVE LOAN COUNT | J4: TOTAL ORIGINAL BORROWED
B5: =SUM(E9:E31) -> 2263000 | D5: =SUM(F9:F31) -> 107550 | F5: =MAX(G9:G31) -> 0.36 | H5: =COUNTA(B9:B31) -> 23 | J5: =SUM(D9:D31) -> 2344000
B6: Across all active liabilities | D6: Fixed regular monthly commitments | F6: Peak annual rate (Avalanche priority) | H6: Tracked loan accounts | J6: Initial total sanctioned debt
B8: Liability / Loan Name | C8: Category | D8: Original Borrowed | E8: Outstanding Balance | F8: Monthly EMI | G8: Interest Rate | H8: Start Date | I8: End Date | J8: Priority | K8: Notes & Status
B9: ICICI Credit Card | C9: Credit Card | D9: 30000 | E9: 9000 | F9: 8950 | G9: 0.18 | H9: 45931 | I9: 46300 | J9: Priority 2 - Medium | K9: Card EMI payoff
B10: Cred 1 | C10: Credit Card | D10: 20000 | E10: 8000 | F10: 2800 | G10: 0.165 | H10: 46113 | I10: 46362 | J10: Priority 2 - Medium | K10: Credit line EMI
B11: Slice | C11: Fintech Credit | D11: 300000 | E11: 175000 | F11: 25600 | G11: 0.26 | H11: 46113 | I11: 46512 | J11: Priority 1 - Urgent | K11: High interest rate (26%)
B12: Cred 2 | C12: Credit Card | D12: 150000 | E12: 122000 | F12: 11300 | G12: 0.165 | H12: 46179 | I12: 46605 | J12: Priority 2 - Medium | K12: Credit line EMI
B13: Piramal Capital | C13: Personal Loan | D13: 700000 | E13: 955000 | F13: 18400 | G13: 0.186 | H13: 46058 | I13: 47884 | J13: Priority 2 - Medium | K13: Long-term NBFC loan
B14: Abba BC | C14: Chit Fund / BC | D14: 200000 | E14: 40000 | F14: 9000 | G14: 0 | I14: 46466 | J14: Priority 3 - 0% EMI | K14: Committee / BC monthly
B15: IDFC First Bank | C15: Personal Loan | D15: 130000 | E15: 170000 | F15: 5000 | G15: 0.23 | H15: 46147 | I15: 47289 | J15: Priority 1 - Urgent | K15: High interest personal loan
B16: Mahila Samiti | C16: Community Loan | D16: 140000 | E16: 150000 | F16: 4500 | G16: 0.36 | J16: Priority 1 - Urgent | K16: ₹4,500 monthly interest (36%)
B17: Riyasat (2k) | C17: Personal Loan | D17: 50000 | E17: 30000 | F17: 2000 | G17: 0 | J17: Priority 3 - 0% EMI | K17: ₹2,000 monthly payment
B18: Riyasat (2ksha) | C18: Personal Loan | D18: 50000 | E18: 40000 | F18: 2000 | G18: 0 | J18: Priority 3 - 0% EMI | K18: ₹2,000 monthly payment
B19: Riyasat (1k) | C19: Personal Loan | D19: 20000 | E19: 10000 | F19: 1000 | G19: 0 | J19: Priority 3 - 0% EMI | K19: ₹1,000 monthly payment
B20: Charku 1 | C20: Personal Loan | D20: 24000 | E20: 24000 | F20: 3000 | G20: 0 | J20: Priority 3 - 0% EMI | K20: ₹3,000 monthly payment
B21: Charku 2 | C21: Personal Loan | D21: 50000 | E21: 50000 | F21: 3000 | G21: 0 | J21: Priority 3 - 0% EMI | K21: ₹3,000 monthly payment
B22: Pinki | C22: Informal Loan | D22: 50000 | E22: 50000 | F22: 0 | G22: 0 | J22: Priority 4 - Flexible | K22: Lump sum repayment
B23: Jewar (Gold Loan) | C23: Secured / Jewel | D23: 35000 | E23: 35000 | F23: 1000 | G23: 0.36 | J23: Priority 1 - Urgent | K23: ₹1,000 monthly interest (36%)
B24: Jalil | C24: Informal Loan | D24: 210000 | E24: 210000 | F24: 0 | G24: 0 | J24: Priority 4 - Flexible | K24: Lump sum repayment
B25: Door Renovation | C25: Vendor / Home | D25: 25000 | E25: 25000 | F25: 0 | G25: 0 | J25: Priority 4 - Flexible | K25: Home vendor pending
B26: Cement Material | C26: Vendor / Home | D26: 50000 | E26: 50000 | F26: 0 | G26: 0 | J26: Priority 4 - Flexible | K26: Construction material
B27: Kalijan | C27: Informal Loan | D27: 30000 | E27: 30000 | F27: 0 | G27: 0 | J27: Priority 4 - Flexible | K27: Family / informal debt
... B31: Home Expenses | C31: Household | D31: 10000 | E31: 10000 | F31: 10000 | G31: 0 | J31: Priority 3 - 0% EMI | K31: Immediate monthly expense
B32: TOTAL PORTFOLIO | D32: =SUM(D9:D31) -> 2344000 | E32: =SUM(E9:E31) -> 2263000 | F32: =SUM(F9:F31) -> 107550 | G32: =AVERAGEIF(G9:G31, ">0") -> 0.23825 | K32: 23 Active Accounts
B33: AVERAGE PER LOAN | D33: =AVERAGE(D9:D31) -> 101913.04 | E33: =AVERAGE(E9:E31) -> 98391.304 | F33: =AVERAGE(F9:F31) -> 4676.087

Sheet Loan_Management
B1: 💳 Comprehensive Loan Repayment & Lump Sum Settlement Tracker | M1: Currency: INR (₹)
B2: Liability / Loan Name | C2: Category | D2: Owner | E2: Original Borrowed | F2: Current Outstanding | G2: Lump Sum Paid | H2: Net Outstanding | I2: Monthly EMI | J2: Interest Rate | K2: Priority | L2: Loan Status | M2: Notes & Status | N2: This Month Lump Sum | O2: Start Date | P2: End Date
B3: =Sheet1!B9 -> ICICI Credit Card | C3: Credit Card | D3: Shahil | E3: =Sheet1!D9 -> 30000 | F3: =Sheet1!E9 -> 9000 | G3: =IF(B3="", "", SUMIFS(Monthly_Repayments!$G$9:$G$200, Monthly_Repayments!$D$9:$D$200, B3, Monthly_Repayments!$F$9:$F$200, "Lump Sum") + SUMIFS(Monthly_Repayments!$G$9:$G$200, Monthly_Repayments!$D$9:$D$200, B3, Monthly_Repayments!$F$9:$F$200, "Full Settlement")) -> 0 | H3: =IF(B3="", "", MAX(0, N(F3)-N(G3))) -> 9000 | I3: =Sheet1!F9 -> 8950 | J3: =Sheet1!G9 -> 0.18 | K3: =Sheet1!J9 -> Priority 2 - Medium | L3: =IF(B3="", "", IF(H3<=0, "Closed", "Open")) -> Open | M3: =Sheet1!K9 -> Card EMI payoff | N3: =IF(B3="", "", SUMIFS(Monthly_Repayments!$G$9:$G$200, Monthly_Repayments!$D$9:$D$200, B3, Monthly_Repayments!$F$9:$F$200, "Lump Sum", Monthly_Repayments!$C$9:$C$200, ">="&DATE(YEAR(TODAY()), MONTH(TODAY()), 1), Monthly_Repayments!$C$9:$C$200, "<="&EOMONTH(TODAY(), 0)) + SUMIFS(Monthly_Repayments!$G$9:$G$200, Monthly_Repayments!$D$9:$D$200, B3, Monthly_Repayments!$F$9:$F$200, "Full Settlement", Monthly_Repayments!$C$9:$C$200, ">="&DATE(YEAR(TODAY()), MONTH(TODAY()), 1), Monthly_Repayments!$C$9:$C$200, "<="&EOMONTH(TODAY(), 0))) -> 0 | O3: =IF(Sheet1!H9="","",Sheet1!H9) -> 45931 | P3: =IF(Sheet1!I9="","",Sheet1!I9) -> 46300
B4: =Sheet1!B10 -> Cred 1 | C4: Credit Card | D4: Shahil | E4: =Sheet1!D10 -> 20000 | F4: =Sheet1!E10 -> 8000 | G4: =IF(B4="", "", SUMIFS(Monthly_Repayments!$G$9:$G$200, Monthly_Repayments!$D$9:$D$200, B4, Monthly_Repayments!$F$9:$F$200, "Lump Sum") + SUMIFS(Monthly_Repayments!$G$9:$G$200, Monthly_Repayments!$D$9:$D$200, B4, Monthly_Repayments!$F$9:$F$200, "Full Settlement")) -> 0 | H4: =IF(B4="", "", MAX(0, N(F4)-N(G4))) -> 8000 | I4: =Sheet1!F10 -> 2800 | J4: =Sheet1!G10 -> 0.165 | K4: =Sheet1!J10 -> Priority 2 - Medium | L4: =IF(B4="", "", IF(H4<=0, "Closed", "Open")) -> Open | M4: =Sheet1!K10 -> Credit line EMI | N4: =IF(B4="", "", SUMIFS(Monthly_Repayments!$G$9:$G$200, Monthly_Repayments!$D$9:$D$200, B4, Monthly_Repayments!$F$9:$F$200, "Lump Sum", Monthly_Repayments!$C$9:$C$200, ">="&DATE(YEAR(TODAY()), MONTH(TODAY()), 1), Monthly_Repayments!$C$9:$C$200, "<="&EOMONTH(TODAY(), 0)) + SUMIFS(Monthly_Repayments!$G$9:$G$200, Monthly_Repayments!$D$9:$D$200, B4, Monthly_Repayments!$F$9:$F$200, "Full Settlement", Monthly_Repayments!$C$9:$C$200, ">="&DATE(YEAR(TODAY()), MONTH(TODAY()), 1), Monthly_Repayments!$C$9:$C$200, "<="&EOMONTH(TODAY(), 0))) -> 0 | O4: =IF(Sheet1!H10="","",Sheet1!H10) -> 46113 | P4: =IF(Sheet1!I10="","",Sheet1!I10) -> 46362
B5: =Sheet1!B11 -> Slice | C5: Fintech Credit | D5: Shahil | E5: =Sheet1!D11 -> 300000 | F5: =Sheet1!E11 -> 175000 | G5: =IF(B5="", "", SUMIFS(Monthly_Repayments!$G$9:$G$200, Monthly_Repayments!$D$9:$D$200, B5, Monthly_Repayments!$F$9:$F$200, "Lump Sum") + SUMIFS(Monthly_Repayments!$G$9:$G$200, Monthly_Repayments!$D$9:$D$200, B5, Monthly_Repayments!$F$9:$F$200, "Full Settlement")) -> 0 | H5: =IF(B5="", "", MAX(0, N(F5)-N(G5))) -> 175000 | I5: =Sheet1!F11 -> 25600 | J5: =Sheet1!G11 -> 0.26 | K5: =Sheet1!J11 -> Priority 1 - Urgent | L5: =IF(B5="", "", IF(H5<=0, "Closed", "Open")) -> Open | M5: =Sheet1!K11 -> High interest rate (26%) | N5: =IF(B5="", "", SUMIFS(Monthly_Repayments!$G$9:$G$200, Monthly_Repayments!$D$9:$D$200, B5, Monthly_Repayments!$F$9:$F$200, "Lump Sum", Monthly_Repayments!$C$9:$C$200, ">="&DATE(YEAR(TODAY()), MONTH(TODAY()), 1), Monthly_Repayments!$C$9:$C$200, "<="&EOMONTH(TODAY(), 0)) + SUMIFS(Monthly_Repayments!$G$9:$G$200, Monthly_Repayments!$D$9:$D$200, B5, Monthly_Repayments!$F$9:$F$200, "Full Settlement", Monthly_Repayments!$C$9:$C$200, ">="&DATE(YEAR(TODAY()), MONTH(TODAY()), 1), Monthly_Repayments!$C$9:$C$200, "<="&EOMONTH(TODAY(), 0))) -> 0 | O5: =IF(Sheet1!H11="","",Sheet1!H11) -> 46113 | P5: =IF(Sheet1!I11="","",Sheet1!I11) -> 46512
B6: =Sheet1!B12 -> Cred 2 | C6: Credit Card | D6: Shahil | E6: =Sheet1!D12 -> 150000 | F6: =Sheet1!E12 -> 122000 | G6: =IF(B6="", "", SUMIFS(Monthly_Repayments!$G$9:$G$200, Monthly_Repayments!$D$9:$D$200, B6, Monthly_Repayments!$F$9:$F$200, "Lump Sum") + SUMIFS(Monthly_Repayments!$G$9:$G$200, Monthly_Repayments!$D$9:$D$200, B6, Monthly_Repayments!$F$9:$F$200, "Full Settlement")) -> 0 | H6: =IF(B6="", "", MAX(0, N(F6)-N(G6))) -> 122000 | I6: =Sheet1!F12 -> 11300 | J6: =Sheet1!G12 -> 0.165 | K6: =Sheet1!J12 -> Priority 2 - Medium | L6: =IF(B6="", "", IF(H6<=0, "Closed", "Open")) -> Open | M6: =Sheet1!K12 -> Credit line EMI | N6: =IF(B6="", "", SUMIFS(Monthly_Repayments!$G$9:$G$200, Monthly_Repayments!$D$9:$D$200, B6, Monthly_Repayments!$F$9:$F$200, "Lump Sum", Monthly_Repayments!$C$9:$C$200, ">="&DATE(YEAR(TODAY()), MONTH(TODAY()), 1), Monthly_Repayments!$C$9:$C$200, "<="&EOMONTH(TODAY(), 0)) + SUMIFS(Monthly_Repayments!$G$9:$G$200, Monthly_Repayments!$D$9:$D$200, B6, Monthly_Repayments!$F$9:$F$200, "Full Settlement", Monthly_Repayments!$C$9:$C$200, ">="&DATE(YEAR(TODAY()), MONTH(TODAY()), 1), Monthly_Repayments!$C$9:$C$200, "<="&EOMONTH(TODAY(), 0))) -> 0 | O6: =IF(Sheet1!H12="","",Sheet1!H12) -> 46179 | P6: =IF(Sheet1!I12="","",Sheet1!I12) -> 46605
B7: =Sheet1!B13 -> Piramal Capital | C7: Personal Loan | D7: Shahil | E7: =Sheet1!D13 -> 700000 | F7: =Sheet1!E13 -> 955000 | G7: =IF(B7="", "", SUMIFS(Monthly_Repayments!$G$9:$G$200, Monthly_Repayments!$D$9:$D$200, B7, Monthly_Repayments!$F$9:$F$200, "Lump Sum") + SUMIFS(Monthly_Repayments!$G$9:$G$200, Monthly_Repayments!$D$9:$D$200, B7, Monthly_Repayments!$F$9:$F$200, "Full Settlement")) -> 0 | H7: =IF(B7="", "", MAX(0, N(F7)-N(G7))) -> 955000 | I7: =Sheet1!F13 -> 18400 | J7: =Sheet1!G13 -> 0.186 | K7: =Sheet1!J13 -> Priority 2 - Medium | L7: =IF(B7="", "", IF(H7<=0, "Closed", "Open")) -> Open | M7: =Sheet1!K13 -> Long-term NBFC loan | N7: =IF(B7="", "", SUMIFS(Monthly_Repayments!$G$9:$G$200, Monthly_Repayments!$D$9:$D$200, B7, Monthly_Repayments!$F$9:$F$200, "Lump Sum", Monthly_Repayments!$C$9:$C$200, ">="&DATE(YEAR(TODAY()), MONTH(TODAY()), 1), Monthly_Repayments!$C$9:$C$200, "<="&EOMONTH(TODAY(), 0)) + SUMIFS(Monthly_Repayments!$G$9:$G$200, Monthly_Repayments!$D$9:$D$200, B7, Monthly_Repayments!$F$9:$F$200, "Full Settlement", Monthly_Repayments!$C$9:$C$200, ">="&DATE(YEAR(TODAY()), MONTH(TODAY()), 1), Monthly_Repayments!$C$9:$C$200, "<="&EOMONTH(TODAY(), 0))) -> 0 | O7: =IF(Sheet1!H13="","",Sheet1!H13) -> 46058 | P7: =IF(Sheet1!I13="","",Sheet1!I13) -> 47884
B8: =Sheet1!B14 -> Abba BC | C8: Chit Fund / BC | D8: Abba | E8: =Sheet1!D14 -> 200000 | F8: =Sheet1!E14 -> 40000 | G8: =IF(B8="", "", SUMIFS(Monthly_Repayments!$G$9:$G$200, Monthly_Repayments!$D$9:$D$200, B8, Monthly_Repayments!$F$9:$F$200, "Lump Sum") + SUMIFS(Monthly_Repayments!$G$9:$G$200, Monthly_Repayments!$D$9:$D$200, B8, Monthly_Repayments!$F$9:$F$200, "Full Settlement")) -> 0 | H8: =IF(B8="", "", MAX(0, N(F8)-N(G8))) -> 40000 | I8: =Sheet1!F14 -> 9000 | J8: =Sheet1!G14 -> 0 | K8: =Sheet1!J14 -> Priority 3 - 0% EMI | L8: =IF(B8="", "", IF(H8<=0, "Closed", "Open")) -> Open | M8: =Sheet1!K14 -> Committee / BC monthly | N8: =IF(B8="", "", SUMIFS(Monthly_Repayments!$G$9:$G$200, Monthly_Repayments!$D$9:$D$200, B8, Monthly_Repayments!$F$9:$F$200, "Lump Sum", Monthly_Repayments!$C$9:$C$200, ">="&DATE(YEAR(TODAY()), MONTH(TODAY()), 1), Monthly_Repayments!$C$9:$C$200, "<="&EOMONTH(TODAY(), 0)) + SUMIFS(Monthly_Repayments!$G$9:$G$200, Monthly_Repayments!$D$9:$D$200, B8, Monthly_Repayments!$F$9:$F$200, "Full Settlement", Monthly_Repayments!$C$9:$C$200, ">="&DATE(YEAR(TODAY()), MONTH(TODAY()), 1), Monthly_Repayments!$C$9:$C$200, "<="&EOMONTH(TODAY(), 0))) -> 0 | O8: =IF(Sheet1!H14="","",Sheet1!H14) | P8: =IF(Sheet1!I14="","",Sheet1!I14) -> 46466
B9: =Sheet1!B15 -> IDFC First Bank | C9: Personal Loan | D9: Ammi | E9: =Sheet1!D15 -> 130000 | F9: =Sheet1!E15 -> 170000 | G9: =IF(B9="", "", SUMIFS(Monthly_Repayments!$G$9:$G$200, Monthly_Repayments!$D$9:$D$200, B9, Monthly_Repayments!$F$9:$F$200, "Lump Sum") + SUMIFS(Monthly_Repayments!$G$9:$G$200, Monthly_Repayments!$D$9:$D$200, B9, Monthly_Repayments!$F$9:$F$200, "Full Settlement")) -> 0 | H9: =IF(B9="", "", MAX(0, N(F9)-N(G9))) -> 170000 | I9: =Sheet1!F15 -> 5000 | J9: =Sheet1!G15 -> 0.23 | K9: =Sheet1!J15 -> Priority 1 - Urgent | L9: =IF(B9="", "", IF(H9<=0, "Closed", "Open")) -> Open | M9: =Sheet1!K15 -> High interest personal loan | N9: =IF(B9="", "", SUMIFS(Monthly_Repayments!$G$9:$G$200, Monthly_Repayments!$D$9:$D$200, B9, Monthly_Repayments!$F$9:$F$200, "Lump Sum", Monthly_Repayments!$C$9:$C$200, ">="&DATE(YEAR(TODAY()), MONTH(TODAY()), 1), Monthly_Repayments!$C$9:$C$200, "<="&EOMONTH(TODAY(), 0)) + SUMIFS(Monthly_Repayments!$G$9:$G$200, Monthly_Repayments!$D$9:$D$200, B9, Monthly_Repayments!$F$9:$F$200, "Full Settlement", Monthly_Repayments!$C$9:$C$200, ">="&DATE(YEAR(TODAY()), MONTH(TODAY()), 1), Monthly_Repayments!$C$9:$C$200, "<="&EOMONTH(TODAY(), 0))) -> 0 | O9: =IF(Sheet1!H15="","",Sheet1!H15) -> 46147 | P9: =IF(Sheet1!I15="","",Sheet1!I15) -> 47289
B10: =Sheet1!B16 -> Mahila Samiti | C10: Community Loan | D10: Ammi | E10: =Sheet1!D16 -> 140000 | F10: =Sheet1!E16 -> 150000 | G10: =IF(B10="", "", SUMIFS(Monthly_Repayments!$G$9:$G$200, Monthly_Repayments!$D$9:$D$200, B10, Monthly_Repayments!$F$9:$F$200, "Lump Sum") + SUMIFS(Monthly_Repayments!$G$9:$G$200, Monthly_Repayments!$D$9:$D$200, B10, Monthly_Repayments!$F$9:$F$200, "Full Settlement")) -> 0 | H10: =IF(B10="", "", MAX(0, N(F10)-N(G10))) -> 150000 | I10: =Sheet1!F16 -> 4500 | J10: =Sheet1!G16 -> 0.36 | K10: =Sheet1!J16 -> Priority 1 - Urgent | L10: =IF(B10="", "", IF(H10<=0, "Closed", "Open")) -> Open | M10: =Sheet1!K16 -> ₹4,500 monthly interest (36%) | N10: =IF(B10="", "", SUMIFS(Monthly_Repayments!$G$9:$G$200, Monthly_Repayments!$D$9:$D$200, B10, Monthly_Repayments!$F$9:$F$200, "Lump Sum", Monthly_Repayments!$C$9:$C$200, ">="&DATE(YEAR(TODAY()), MONTH(TODAY()), 1), Monthly_Repayments!$C$9:$C$200, "<="&EOMONTH(TODAY(), 0)) + SUMIFS(Monthly_Repayments!$G$9:$G$200, Monthly_Repayments!$D$9:$D$200, B10, Monthly_Repayments!$F$9:$F$200, "Full Settlement", Monthly_Repayments!$C$9:$C$200, ">="&DATE(YEAR(TODAY()), MONTH(TODAY()), 1), Monthly_Repayments!$C$9:$C$200, "<="&EOMONTH(TODAY(), 0))) -> 0 | O10: =IF(Sheet1!H16="","",Sheet1!H16) | P10: =IF(Sheet1!I16="","",Sheet1!I16)
B11: =Sheet1!B17 -> Riyasat (2k) | C11: Personal Loan | D11: Mukhtar | E11: =Sheet1!D17 -> 50000 | F11: =Sheet1!E17 -> 30000 | G11: =IF(B11="", "", SUMIFS(Monthly_Repayments!$G$9:$G$200, Monthly_Repayments!$D$9:$D$200, B11, Monthly_Repayments!$F$9:$F$200, "Lump Sum") + SUMIFS(Monthly_Repayments!$G$9:$G$200, Monthly_Repayments!$D$9:$D$200, B11, Monthly_Repayments!$F$9:$F$200, "Full Settlement")) -> 0 | H11: =IF(B11="", "", MAX(0, N(F11)-N(G11))) -> 30000 | I11: =Sheet1!F17 -> 2000 | J11: =Sheet1!G17 -> 0 | K11: =Sheet1!J17 -> Priority 3 - 0% EMI | L11: =IF(B11="", "", IF(H11<=0, "Closed", "Open")) -> Open | M11: =Sheet1!K17 -> ₹2,000 monthly payment | N11: =IF(B11="", "", SUMIFS(Monthly_Repayments!$G$9:$G$200, Monthly_Repayments!$D$9:$D$200, B11, Monthly_Repayments!$F$9:$F$200, "Lump Sum", Monthly_Repayments!$C$9:$C$200, ">="&DATE(YEAR(TODAY()), MONTH(TODAY()), 1), Monthly_Repayments!$C$9:$C$200, "<="&EOMONTH(TODAY(), 0)) + SUMIFS(Monthly_Repayments!$G$9:$G$200, Monthly_Repayments!$D$9:$D$200, B11, Monthly_Repayments!$F$9:$F$200, "Full Settlement", Monthly_Repayments!$C$9:$C$200, ">="&DATE(YEAR(TODAY()), MONTH(TODAY()), 1), Monthly_Repayments!$C$9:$C$200, "<="&EOMONTH(TODAY(), 0))) -> 0 | O11: =IF(Sheet1!H17="","",Sheet1!H17) | P11: =IF(Sheet1!I17="","",Sheet1!I17)
B12: =Sheet1!B18 -> Riyasat (2ksha) | C12: Personal Loan | D12: Shahil | E12: =Sheet1!D18 -> 50000 | F12: =Sheet1!E18 -> 40000 | G12: =IF(B12="", "", SUMIFS(Monthly_Repayments!$G$9:$G$200, Monthly_Repayments!$D$9:$D$200, B12, Monthly_Repayments!$F$9:$F$200, "Lump Sum") + SUMIFS(Monthly_Repayments!$G$9:$G$200, Monthly_Repayments!$D$9:$D$200, B12, Monthly_Repayments!$F$9:$F$200, "Full Settlement")) -> 0 | H12: =IF(B12="", "", MAX(0, N(F12)-N(G12))) -> 40000 | I12: =Sheet1!F18 -> 2000 | J12: =Sheet1!G18 -> 0 | K12: =Sheet1!J18 -> Priority 3 - 0% EMI | L12: =IF(B12="", "", IF(H12<=0, "Closed", "Open")) -> Open | M12: =Sheet1!K18 -> ₹2,000 monthly payment | N12: =IF(B12="", "", SUMIFS(Monthly_Repayments!$G$9:$G$200, Monthly_Repayments!$D$9:$D$200, B12, Monthly_Repayments!$F$9:$F$200, "Lump Sum", Monthly_Repayments!$C$9:$C$200, ">="&DATE(YEAR(TODAY()), MONTH(TODAY()), 1), Monthly_Repayments!$C$9:$C$200, "<="&EOMONTH(TODAY(), 0)) + SUMIFS(Monthly_Repayments!$G$9:$G$200, Monthly_Repayments!$D$9:$D$200, B12, Monthly_Repayments!$F$9:$F$200, "Full Settlement", Monthly_Repayments!$C$9:$C$200, ">="&DATE(YEAR(TODAY()), MONTH(TODAY()), 1), Monthly_Repayments!$C$9:$C$200, "<="&EOMONTH(TODAY(), 0))) -> 0 | O12: =IF(Sheet1!H18="","",Sheet1!H18) | P12: =IF(Sheet1!I18="","",Sheet1!I18)
B13: =Sheet1!B19 -> Riyasat (1k) | C13: Personal Loan | D13: Mukhtar | E13: =Sheet1!D19 -> 20000 | F13: =Sheet1!E19 -> 10000 | G13: =IF(B13="", "", SUMIFS(Monthly_Repayments!$G$9:$G$200, Monthly_Repayments!$D$9:$D$200, B13, Monthly_Repayments!$F$9:$F$200, "Lump Sum") + SUMIFS(Monthly_Repayments!$G$9:$G$200, Monthly_Repayments!$D$9:$D$200, B13, Monthly_Repayments!$F$9:$F$200, "Full Settlement")) -> 0 | H13: =IF(B13="", "", MAX(0, N(F13)-N(G13))) -> 10000 | I13: =Sheet1!F19 -> 1000 | J13: =Sheet1!G19 -> 0 | K13: =Sheet1!J19 -> Priority 3 - 0% EMI | L13: =IF(B13="", "", IF(H13<=0, "Closed", "Open")) -> Open | M13: =Sheet1!K19 -> ₹1,000 monthly payment | N13: =IF(B13="", "", SUMIFS(Monthly_Repayments!$G$9:$G$200, Monthly_Repayments!$D$9:$D$200, B13, Monthly_Repayments!$F$9:$F$200, "Lump Sum", Monthly_Repayments!$C$9:$C$200, ">="&DATE(YEAR(TODAY()), MONTH(TODAY()), 1), Monthly_Repayments!$C$9:$C$200, "<="&EOMONTH(TODAY(), 0)) + SUMIFS(Monthly_Repayments!$G$9:$G$200, Monthly_Repayments!$D$9:$D$200, B13, Monthly_Repayments!$F$9:$F$200, "Full Settlement", Monthly_Repayments!$C$9:$C$200, ">="&DATE(YEAR(TODAY()), MONTH(TODAY()), 1), Monthly_Repayments!$C$9:$C$200, "<="&EOMONTH(TODAY(), 0))) -> 0 | O13: =IF(Sheet1!H19="","",Sheet1!H19) | P13: =IF(Sheet1!I19="","",Sheet1!I19)
B14: =Sheet1!B20 -> Charku 1 | C14: Personal Loan | D14: Israfil | E14: =Sheet1!D20 -> 24000 | F14: =Sheet1!E20 -> 24000 | G14: =IF(B14="", "", SUMIFS(Monthly_Repayments!$G$9:$G$200, Monthly_Repayments!$D$9:$D$200, B14, Monthly_Repayments!$F$9:$F$200, "Lump Sum") + SUMIFS(Monthly_Repayments!$G$9:$G$200, Monthly_Repayments!$D$9:$D$200, B14, Monthly_Repayments!$F$9:$F$200, "Full Settlement")) -> 0 | H14: =IF(B14="", "", MAX(0, N(F14)-N(G14))) -> 24000 | I14: =Sheet1!F20 -> 3000 | J14: =Sheet1!G20 -> 0 | K14: =Sheet1!J20 -> Priority 3 - 0% EMI | L14: =IF(B14="", "", IF(H14<=0, "Closed", "Open")) -> Open | M14: =Sheet1!K20 -> ₹3,000 monthly payment | N14: =IF(B14="", "", SUMIFS(Monthly_Repayments!$G$9:$G$200, Monthly_Repayments!$D$9:$D$200, B14, Monthly_Repayments!$F$9:$F$200, "Lump Sum", Monthly_Repayments!$C$9:$C$200, ">="&DATE(YEAR(TODAY()), MONTH(TODAY()), 1), Monthly_Repayments!$C$9:$C$200, "<="&EOMONTH(TODAY(), 0)) + SUMIFS(Monthly_Repayments!$G$9:$G$200, Monthly_Repayments!$D$9:$D$200, B14, Monthly_Repayments!$F$9:$F$200, "Full Settlement", Monthly_Repayments!$C$9:$C$200, ">="&DATE(YEAR(TODAY()), MONTH(TODAY()), 1), Monthly_Repayments!$C$9:$C$200, "<="&EOMONTH(TODAY(), 0))) -> 0 | O14: =IF(Sheet1!H20="","",Sheet1!H20) | P14: =IF(Sheet1!I20="","",Sheet1!I20)
... B25: =Sheet1!B31 -> Home Expenses | C25: Household | D25: Others | E25: =Sheet1!D31 -> 10000 | F25: =Sheet1!E31 -> 10000 | G25: =IF(B25="", "", SUMIFS(Monthly_Repayments!$G$9:$G$200, Monthly_Repayments!$D$9:$D$200, B25, Monthly_Repayments!$F$9:$F$200, "Lump Sum") + SUMIFS(Monthly_Repayments!$G$9:$G$200, Monthly_Repayments!$D$9:$D$200, B25, Monthly_Repayments!$F$9:$F$200, "Full Settlement")) -> 0 | H25: =IF(B25="", "", MAX(0, N(F25)-N(G25))) -> 10000 | I25: =Sheet1!F31 -> 10000 | J25: =Sheet1!G31 -> 0 | K25: =Sheet1!J31 -> Priority 3 - 0% EMI | L25: =IF(B25="", "", IF(H25<=0, "Closed", "Open")) -> Open | M25: =Sheet1!K31 -> Immediate monthly expense | N25: =IF(B25="", "", SUMIFS(Monthly_Repayments!$G$9:$G$200, Monthly_Repayments!$D$9:$D$200, B25, Monthly_Repayments!$F$9:$F$200, "Lump Sum", Monthly_Repayments!$C$9:$C$200, ">="&DATE(YEAR(TODAY()), MONTH(TODAY()), 1), Monthly_Repayments!$C$9:$C$200, "<="&EOMONTH(TODAY(), 0)) + SUMIFS(Monthly_Repayments!$G$9:$G$200, Monthly_Repayments!$D$9:$D$200, B25, Monthly_Repayments!$F$9:$F$200, "Full Settlement", Monthly_Repayments!$C$9:$C$200, ">="&DATE(YEAR(TODAY()), MONTH(TODAY()), 1), Monthly_Repayments!$C$9:$C$200, "<="&EOMONTH(TODAY(), 0))) -> 0 | O25: =IF(Sheet1!H31="","",Sheet1!H31) | P25: =IF(Sheet1!I31="","",Sheet1!I31)
G26: =IF(B26="", "", SUMIFS(Monthly_Repayments!$G$9:$G$200, Monthly_Repayments!$D$9:$D$200, B26, Monthly_Repayments!$F$9:$F$200, "Lump Sum") + SUMIFS(Monthly_Repayments!$G$9:$G$200, Monthly_Repayments!$D$9:$D$200, B26, Monthly_Repayments!$F$9:$F$200, "Full Settlement")) | H26: =IF(B26="", "", MAX(0, N(F26)-N(G26))) | L26: =IF(B26="", "", IF(H26<=0, "Closed", "Open")) | N26: =IF(B26="", "", SUMIFS(Monthly_Repayments!$G$9:$G$200, Monthly_Repayments!$D$9:$D$200, B26, Monthly_Repayments!$F$9:$F$200, "Lump Sum", Monthly_Repayments!$C$9:$C$200, ">="&DATE(YEAR(TODAY()), MONTH(TODAY()), 1), Monthly_Repayments!$C$9:$C$200, "<="&EOMONTH(TODAY(), 0)) + SUMIFS(Monthly_Repayments!$G$9:$G$200, Monthly_Repayments!$D$9:$D$200, B26, Monthly_Repayments!$F$9:$F$200, "Full Settlement", Monthly_Repayments!$C$9:$C$200, ">="&DATE(YEAR(TODAY()), MONTH(TODAY()), 1), Monthly_Repayments!$C$9:$C$200, "<="&EOMONTH(TODAY(), 0)))
G27: =IF(B27="", "", SUMIFS(Monthly_Repayments!$G$9:$G$200, Monthly_Repayments!$D$9:$D$200, B27, Monthly_Repayments!$F$9:$F$200, "Lump Sum") + SUMIFS(Monthly_Repayments!$G$9:$G$200, Monthly_Repayments!$D$9:$D$200, B27, Monthly_Repayments!$F$9:$F$200, "Full Settlement")) | H27: =IF(B27="", "", MAX(0, N(F27)-N(G27))) | L27: =IF(B27="", "", IF(H27<=0, "Closed", "Open")) | N27: =IF(B27="", "", SUMIFS(Monthly_Repayments!$G$9:$G$200, Monthly_Repayments!$D$9:$D$200, B27, Monthly_Repayments!$F$9:$F$200, "Lump Sum", Monthly_Repayments!$C$9:$C$200, ">="&DATE(YEAR(TODAY()), MONTH(TODAY()), 1), Monthly_Repayments!$C$9:$C$200, "<="&EOMONTH(TODAY(), 0)) + SUMIFS(Monthly_Repayments!$G$9:$G$200, Monthly_Repayments!$D$9:$D$200, B27, Monthly_Repayments!$F$9:$F$200, "Full Settlement", Monthly_Repayments!$C$9:$C$200, ">="&DATE(YEAR(TODAY()), MONTH(TODAY()), 1), Monthly_Repayments!$C$9:$C$200, "<="&EOMONTH(TODAY(), 0)))
G28: =IF(B28="", "", SUMIFS(Monthly_Repayments!$G$9:$G$200, Monthly_Repayments!$D$9:$D$200, B28, Monthly_Repayments!$F$9:$F$200, "Lump Sum") + SUMIFS(Monthly_Repayments!$G$9:$G$200, Monthly_Repayments!$D$9:$D$200, B28, Monthly_Repayments!$F$9:$F$200, "Full Settlement")) | H28: =IF(B28="", "", MAX(0, N(F28)-N(G28))) | L28: =IF(B28="", "", IF(H28<=0, "Closed", "Open")) | N28: =IF(B28="", "", SUMIFS(Monthly_Repayments!$G$9:$G$200, Monthly_Repayments!$D$9:$D$200, B28, Monthly_Repayments!$F$9:$F$200, "Lump Sum", Monthly_Repayments!$C$9:$C$200, ">="&DATE(YEAR(TODAY()), MONTH(TODAY()), 1), Monthly_Repayments!$C$9:$C$200, "<="&EOMONTH(TODAY(), 0)) + SUMIFS(Monthly_Repayments!$G$9:$G$200, Monthly_Repayments!$D$9:$D$200, B28, Monthly_Repayments!$F$9:$F$200, "Full Settlement", Monthly_Repayments!$C$9:$C$200, ">="&DATE(YEAR(TODAY()), MONTH(TODAY()), 1), Monthly_Repayments!$C$9:$C$200, "<="&EOMONTH(TODAY(), 0)))
G29: =IF(B29="", "", SUMIFS(Monthly_Repayments!$G$9:$G$200, Monthly_Repayments!$D$9:$D$200, B29, Monthly_Repayments!$F$9:$F$200, "Lump Sum") + SUMIFS(Monthly_Repayments!$G$9:$G$200, Monthly_Repayments!$D$9:$D$200, B29, Monthly_Repayments!$F$9:$F$200, "Full Settlement")) | H29: =IF(B29="", "", MAX(0, N(F29)-N(G29))) | L29: =IF(B29="", "", IF(H29<=0, "Closed", "Open")) | N29: =IF(B29="", "", SUMIFS(Monthly_Repayments!$G$9:$G$200, Monthly_Repayments!$D$9:$D$200, B29, Monthly_Repayments!$F$9:$F$200, "Lump Sum", Monthly_Repayments!$C$9:$C$200, ">="&DATE(YEAR(TODAY()), MONTH(TODAY()), 1), Monthly_Repayments!$C$9:$C$200, "<="&EOMONTH(TODAY(), 0)) + SUMIFS(Monthly_Repayments!$G$9:$G$200, Monthly_Repayments!$D$9:$D$200, B29, Monthly_Repayments!$F$9:$F$200, "Full Settlement", Monthly_Repayments!$C$9:$C$200, ">="&DATE(YEAR(TODAY()), MONTH(TODAY()), 1), Monthly_Repayments!$C$9:$C$200, "<="&EOMONTH(TODAY(), 0)))
G30: =IF(B30="", "", SUMIFS(Monthly_Repayments!$G$9:$G$200, Monthly_Repayments!$D$9:$D$200, B30, Monthly_Repayments!$F$9:$F$200, "Lump Sum") + SUMIFS(Monthly_Repayments!$G$9:$G$200, Monthly_Repayments!$D$9:$D$200, B30, Monthly_Repayments!$F$9:$F$200, "Full Settlement")) | H30: =IF(B30="", "", MAX(0, N(F30)-N(G30))) | L30: =IF(B30="", "", IF(H30<=0, "Closed", "Open")) | N30: =IF(B30="", "", SUMIFS(Monthly_Repayments!$G$9:$G$200, Monthly_Repayments!$D$9:$D$200, B30, Monthly_Repayments!$F$9:$F$200, "Lump Sum", Monthly_Repayments!$C$9:$C$200, ">="&DATE(YEAR(TODAY()), MONTH(TODAY()), 1), Monthly_Repayments!$C$9:$C$200, "<="&EOMONTH(TODAY(), 0)) + SUMIFS(Monthly_Repayments!$G$9:$G$200, Monthly_Repayments!$D$9:$D$200, B30, Monthly_Repayments!$F$9:$F$200, "Full Settlement", Monthly_Repayments!$C$9:$C$200, ">="&DATE(YEAR(TODAY()), MONTH(TODAY()), 1), Monthly_Repayments!$C$9:$C$200, "<="&EOMONTH(TODAY(), 0)))
G31: =IF(B31="", "", SUMIFS(Monthly_Repayments!$G$9:$G$200, Monthly_Repayments!$D$9:$D$200, B31, Monthly_Repayments!$F$9:$F$200, "Lump Sum") + SUMIFS(Monthly_Repayments!$G$9:$G$200, Monthly_Repayments!$D$9:$D$200, B31, Monthly_Repayments!$F$9:$F$200, "Full Settlement")) | H31: =IF(B31="", "", MAX(0, N(F31)-N(G31))) | L31: =IF(B31="", "", IF(H31<=0, "Closed", "Open")) | N31: =IF(B31="", "", SUMIFS(Monthly_Repayments!$G$9:$G$200, Monthly_Repayments!$D$9:$D$200, B31, Monthly_Repayments!$F$9:$F$200, "Lump Sum", Monthly_Repayments!$C$9:$C$200, ">="&DATE(YEAR(TODAY()), MONTH(TODAY()), 1), Monthly_Repayments!$C$9:$C$200, "<="&EOMONTH(TODAY(), 0)) + SUMIFS(Monthly_Repayments!$G$9:$G$200, Monthly_Repayments!$D$9:$D$200, B31, Monthly_Repayments!$F$9:$F$200, "Full Settlement", Monthly_Repayments!$C$9:$C$200, ">="&DATE(YEAR(TODAY()), MONTH(TODAY()), 1), Monthly_Repayments!$C$9:$C$200, "<="&EOMONTH(TODAY(), 0)))
G32: =IF(B32="", "", SUMIFS(Monthly_Repayments!$G$9:$G$200, Monthly_Repayments!$D$9:$D$200, B32, Monthly_Repayments!$F$9:$F$200, "Lump Sum") + SUMIFS(Monthly_Repayments!$G$9:$G$200, Monthly_Repayments!$D$9:$D$200, B32, Monthly_Repayments!$F$9:$F$200, "Full Settlement")) | H32: =IF(B32="", "", MAX(0, N(F32)-N(G32))) | L32: =IF(B32="", "", IF(H32<=0, "Closed", "Open")) | N32: =IF(B32="", "", SUMIFS(Monthly_Repayments!$G$9:$G$200, Monthly_Repayments!$D$9:$D$200, B32, Monthly_Repayments!$F$9:$F$200, "Lump Sum", Monthly_Repayments!$C$9:$C$200, ">="&DATE(YEAR(TODAY()), MONTH(TODAY()), 1), Monthly_Repayments!$C$9:$C$200, "<="&EOMONTH(TODAY(), 0)) + SUMIFS(Monthly_Repayments!$G$9:$G$200, Monthly_Repayments!$D$9:$D$200, B32, Monthly_Repayments!$F$9:$F$200, "Full Settlement", Monthly_Repayments!$C$9:$C$200, ">="&DATE(YEAR(TODAY()), MONTH(TODAY()), 1), Monthly_Repayments!$C$9:$C$200, "<="&EOMONTH(TODAY(), 0)))
G33: =IF(B33="", "", SUMIFS(Monthly_Repayments!$G$9:$G$200, Monthly_Repayments!$D$9:$D$200, B33, Monthly_Repayments!$F$9:$F$200, "Lump Sum") + SUMIFS(Monthly_Repayments!$G$9:$G$200, Monthly_Repayments!$D$9:$D$200, B33, Monthly_Repayments!$F$9:$F$200, "Full Settlement")) | H33: =IF(B33="", "", MAX(0, N(F33)-N(G33))) | L33: =IF(B33="", "", IF(H33<=0, "Closed", "Open")) | N33: =IF(B33="", "", SUMIFS(Monthly_Repayments!$G$9:$G$200, Monthly_Repayments!$D$9:$D$200, B33, Monthly_Repayments!$F$9:$F$200, "Lump Sum", Monthly_Repayments!$C$9:$C$200, ">="&DATE(YEAR(TODAY()), MONTH(TODAY()), 1), Monthly_Repayments!$C$9:$C$200, "<="&EOMONTH(TODAY(), 0)) + SUMIFS(Monthly_Repayments!$G$9:$G$200, Monthly_Repayments!$D$9:$D$200, B33, Monthly_Repayments!$F$9:$F$200, "Full Settlement", Monthly_Repayments!$C$9:$C$200, ">="&DATE(YEAR(TODAY()), MONTH(TODAY()), 1), Monthly_Repayments!$C$9:$C$200, "<="&EOMONTH(TODAY(), 0)))
G34: =IF(B34="", "", SUMIFS(Monthly_Repayments!$G$9:$G$200, Monthly_Repayments!$D$9:$D$200, B34, Monthly_Repayments!$F$9:$F$200, "Lump Sum") + SUMIFS(Monthly_Repayments!$G$9:$G$200, Monthly_Repayments!$D$9:$D$200, B34, Monthly_Repayments!$F$9:$F$200, "Full Settlement")) | H34: =IF(B34="", "", MAX(0, N(F34)-N(G34))) | L34: =IF(B34="", "", IF(H34<=0, "Closed", "Open")) | N34: =IF(B34="", "", SUMIFS(Monthly_Repayments!$G$9:$G$200, Monthly_Repayments!$D$9:$D$200, B34, Monthly_Repayments!$F$9:$F$200, "Lump Sum", Monthly_Repayments!$C$9:$C$200, ">="&DATE(YEAR(TODAY()), MONTH(TODAY()), 1), Monthly_Repayments!$C$9:$C$200, "<="&EOMONTH(TODAY(), 0)) + SUMIFS(Monthly_Repayments!$G$9:$G$200, Monthly_Repayments!$D$9:$D$200, B34, Monthly_Repayments!$F$9:$F$200, "Full Settlement", Monthly_Repayments!$C$9:$C$200, ">="&DATE(YEAR(TODAY()), MONTH(TODAY()), 1), Monthly_Repayments!$C$9:$C$200, "<="&EOMONTH(TODAY(), 0)))
G35: =IF(B35="", "", SUMIFS(Monthly_Repayments!$G$9:$G$200, Monthly_Repayments!$D$9:$D$200, B35, Monthly_Repayments!$F$9:$F$200, "Lump Sum") + SUMIFS(Monthly_Repayments!$G$9:$G$200, Monthly_Repayments!$D$9:$D$200, B35, Monthly_Repayments!$F$9:$F$200, "Full Settlement")) | H35: =IF(B35="", "", MAX(0, N(F35)-N(G35))) | L35: =IF(B35="", "", IF(H35<=0, "Closed", "Open")) | N35: =IF(B35="", "", SUMIFS(Monthly_Repayments!$G$9:$G$200, Monthly_Repayments!$D$9:$D$200, B35, Monthly_Repayments!$F$9:$F$200, "Lump Sum", Monthly_Repayments!$C$9:$C$200, ">="&DATE(YEAR(TODAY()), MONTH(TODAY()), 1), Monthly_Repayments!$C$9:$C$200, "<="&EOMONTH(TODAY(), 0)) + SUMIFS(Monthly_Repayments!$G$9:$G$200, Monthly_Repayments!$D$9:$D$200, B35, Monthly_Repayments!$F$9:$F$200, "Full Settlement", Monthly_Repayments!$C$9:$C$200, ">="&DATE(YEAR(TODAY()), MONTH(TODAY()), 1), Monthly_Repayments!$C$9:$C$200, "<="&EOMONTH(TODAY(), 0)))
G36: =IF(B36="", "", SUMIFS(Monthly_Repayments!$G$9:$G$200, Monthly_Repayments!$D$9:$D$200, B36, Monthly_Repayments!$F$9:$F$200, "Lump Sum") + SUMIFS(Monthly_Repayments!$G$9:$G$200, Monthly_Repayments!$D$9:$D$200, B36, Monthly_Repayments!$F$9:$F$200, "Full Settlement")) | H36: =IF(B36="", "", MAX(0, N(F36)-N(G36))) | L36: =IF(B36="", "", IF(H36<=0, "Closed", "Open")) | N36: =IF(B36="", "", SUMIFS(Monthly_Repayments!$G$9:$G$200, Monthly_Repayments!$D$9:$D$200, B36, Monthly_Repayments!$F$9:$F$200, "Lump Sum", Monthly_Repayments!$C$9:$C$200, ">="&DATE(YEAR(TODAY()), MONTH(TODAY()), 1), Monthly_Repayments!$C$9:$C$200, "<="&EOMONTH(TODAY(), 0)) + SUMIFS(Monthly_Repayments!$G$9:$G$200, Monthly_Repayments!$D$9:$D$200, B36, Monthly_Repayments!$F$9:$F$200, "Full Settlement", Monthly_Repayments!$C$9:$C$200, ">="&DATE(YEAR(TODAY()), MONTH(TODAY()), 1), Monthly_Repayments!$C$9:$C$200, "<="&EOMONTH(TODAY(), 0)))
G37: =IF(B37="", "", SUMIFS(Monthly_Repayments!$G$9:$G$200, Monthly_Repayments!$D$9:$D$200, B37, Monthly_Repayments!$F$9:$F$200, "Lump Sum") + SUMIFS(Monthly_Repayments!$G$9:$G$200, Monthly_Repayments!$D$9:$D$200, B37, Monthly_Repayments!$F$9:$F$200, "Full Settlement")) | H37: =IF(B37="", "", MAX(0, N(F37)-N(G37))) | L37: =IF(B37="", "", IF(H37<=0, "Closed", "Open")) | N37: =IF(B37="", "", SUMIFS(Monthly_Repayments!$G$9:$G$200, Monthly_Repayments!$D$9:$D$200, B37, Monthly_Repayments!$F$9:$F$200, "Lump Sum", Monthly_Repayments!$C$9:$C$200, ">="&DATE(YEAR(TODAY()), MONTH(TODAY()), 1), Monthly_Repayments!$C$9:$C$200, "<="&EOMONTH(TODAY(), 0)) + SUMIFS(Monthly_Repayments!$G$9:$G$200, Monthly_Repayments!$D$9:$D$200, B37, Monthly_Repayments!$F$9:$F$200, "Full Settlement", Monthly_Repayments!$C$9:$C$200, ">="&DATE(YEAR(TODAY()), MONTH(TODAY()), 1), Monthly_Repayments!$C$9:$C$200, "<="&EOMONTH(TODAY(), 0)))
... G49: =IF(B49="", "", SUMIFS(Monthly_Repayments!$G$9:$G$200, Monthly_Repayments!$D$9:$D$200, B49, Monthly_Repayments!$F$9:$F$200, "Lump Sum") + SUMIFS(Monthly_Repayments!$G$9:$G$200, Monthly_Repayments!$D$9:$D$200, B49, Monthly_Repayments!$F$9:$F$200, "Full Settlement")) | H49: =IF(B49="", "", MAX(0, N(F49)-N(G49))) | L49: =IF(B49="", "", IF(H49<=0, "Closed", "Open")) | N49: =IF(B49="", "", SUMIFS(Monthly_Repayments!$G$9:$G$200, Monthly_Repayments!$D$9:$D$200, B49, Monthly_Repayments!$F$9:$F$200, "Lump Sum", Monthly_Repayments!$C$9:$C$200, ">="&DATE(YEAR(TODAY()), MONTH(TODAY()), 1), Monthly_Repayments!$C$9:$C$200, "<="&EOMONTH(TODAY(), 0)) + SUMIFS(Monthly_Repayments!$G$9:$G$200, Monthly_Repayments!$D$9:$D$200, B49, Monthly_Repayments!$F$9:$F$200, "Full Settlement", Monthly_Repayments!$C$9:$C$200, ">="&DATE(YEAR(TODAY()), MONTH(TODAY()), 1), Monthly_Repayments!$C$9:$C$200, "<="&EOMONTH(TODAY(), 0)))
B50: TOTAL PORTFOLIO | E50: =SUM(E3:E49) -> 2344000 | F50: =SUM(F3:F49) -> 2263000 | G50: =SUM(G3:G49) -> 0 | H50: =SUM(H3:H49) -> 2263000 | I50: =SUM(I3:I49) -> 107550 | J50: =IF(SUM(H3:H49)>0, SUMPRODUCT(H3:H49, J3:J49)/SUM(H3:H49), 0) -> 0.15550155 | L50: =COUNTIF(L3:L49, "Open") & " Open / " & COUNTIF(L3:L49, "Closed") & " Closed" -> 23 Open / 0 Closed | M50: =COUNTIF(B3:B49, "<>") & " Active Accounts" -> 23 Active Accounts | N50: =SUM(N3:N49) -> 0
B51: AVERAGE PER LOAN | E51: =IFERROR(AVERAGEIF(B3:B49, "<>", E3:E49), 0) -> 101913.04 | F51: =IFERROR(AVERAGEIF(B3:B49, "<>", F3:F49), 0) -> 98391.304 | G51: =IFERROR(AVERAGEIF(B3:B49, "<>", G3:G49), 0) -> 0 | H51: =IFERROR(AVERAGEIF(B3:B49, "<>", H3:H49), 0) -> 98391.304 | I51: =IFERROR(AVERAGEIF(B3:B49, "<>", I3:I49), 0) -> 4676.087 | J51: =IFERROR(AVERAGEIF(B3:B49, "<>", J3:J49), 0) -> 0.082869565 | N51: =IFERROR(AVERAGEIF(B3:B49, "<>", N3:N49), 0) -> 0

Sheet Dashboard
B2: 📊 Executive Debt & Repayment Portfolio Dashboard | J2: Portfolio Currency: INR (₹) • Live Tracker
B4: 👤 PORTFOLIO OWNER | D4: 📂 LOAN CATEGORY | F4: ⚡ LOAN STATUS | H4: 🔘 PAYMENT VIEW (EMI vs LUMP SUM)
B5: All Owners | D5: All Categories | F5: All Status | H5: Lump Sum View
B7: TOTAL OUTSTANDING | D7: MONTHLY EMI OUTFLOW | F7: TOTAL LUMP SUM PAID | H7: CURRENT MONTH LUMP SUM PAY | J7: LOAN STATUS (OPEN / CLOSED)
B8: =SUMIFS(Loan_Management!$H$3:$H$49, Loan_Management!$D$3:$D$49, IF($B$5="All Owners", "*", $B$5), Loan_Management!$C$3:$C$49, IF($D$5="All Categories", "*", $D$5), Loan_Management!$L$3:$L$49, IF($F$5="All Status", "*", $F$5)) -> 2263000 | D8: =SUMIFS(Loan_Management!$I$3:$I$49, Loan_Management!$D$3:$D$49, IF($B$5="All Owners", "*", $B$5), Loan_Management!$C$3:$C$49, IF($D$5="All Categories", "*", $D$5), Loan_Management!$L$3:$L$49, IF($F$5="All Status", "*", $F$5)) -> 107550 | F8: =SUMIFS(Loan_Management!$G$3:$G$49, Loan_Management!$D$3:$D$49, IF($B$5="All Owners", "*", $B$5), Loan_Management!$C$3:$C$49, IF($D$5="All Categories", "*", $D$5), Loan_Management!$L$3:$L$49, IF($F$5="All Status", "*", $F$5)) -> 0 | H8: =SUMIFS(Loan_Management!$N$3:$N$49, Loan_Management!$D$3:$D$49, IF($B$5="All Owners", "*", $B$5), Loan_Management!$C$3:$C$49, IF($D$5="All Categories", "*", $D$5), Loan_Management!$L$3:$L$49, IF($F$5="All Status", "*", $F$5)) -> 0 | J8: =COUNTIFS(Loan_Management!$D$3:$D$49, IF($B$5="All Owners", "*", $B$5), Loan_Management!$C$3:$C$49, IF($D$5="All Categories", "*", $D$5), Loan_Management!$L$3:$L$49, "Open") & " Open / " & COUNTIFS(Loan_Management!$D$3:$D$49, IF($B$5="All Owners", "*", $B$5), Loan_Management!$C$3:$C$49, IF($D$5="All Categories", "*", $D$5), Loan_Management!$L$3:$L$49, "Closed") & " Closed" -> 23 Open / 0 Closed
B9: Net balance remaining | D9: Active regular commitment | F9: Total extra principal paid | H9: Settled in current billing cycle | J9: =COUNTIFS(Loan_Management!$D$3:$D$49, IF($B$5="All Owners", "*", $B$5), Loan_Management!$C$3:$C$49, IF($D$5="All Categories", "*", $D$5), Loan_Management!$L$3:$L$49, IF($F$5="All Status", "*", $F$5)) & " Filtered accounts" -> 23 Filtered accounts
B11: 📊 Category Breakdown & Liability Analysis
B12: Category | C12: Loan Count | D12: Outstanding Balance | E12: =IF($H$5="Lump Sum View", "Lump Sum Paid", "Monthly EMI") -> Lump Sum Paid | F12: Avg Interest | G12: % Share
B13: Personal Loan | C13: =IF(OR($D$5="All Categories", $D$5=B13), COUNTIFS(Loan_Management!$C$3:$C$49, B13, Loan_Management!$D$3:$D$49, IF($B$5="All Owners", "*", $B$5), Loan_Management!$L$3:$L$49, IF($F$5="All Status", "*", $F$5)), 0) -> 7 | D13: =IF(OR($D$5="All Categories", $D$5=B13), SUMIFS(Loan_Management!$H$3:$H$49, Loan_Management!$C$3:$C$49, B13, Loan_Management!$D$3:$D$49, IF($B$5="All Owners", "*", $B$5), Loan_Management!$L$3:$L$49, IF($F$5="All Status", "*", $F$5)), 0) -> 1279000 | E13: =IF(OR($D$5="All Categories", $D$5=B13), IF($H$5="Lump Sum View", SUMIFS(Loan_Management!$G$3:$G$49, Loan_Management!$C$3:$C$49, B13, Loan_Management!$D$3:$D$49, IF($B$5="All Owners", "*", $B$5), Loan_Management!$L$3:$L$49, IF($F$5="All Status", "*", $F$5)), SUMIFS(Loan_Management!$I$3:$I$49, Loan_Management!$C$3:$C$49, B13, Loan_Management!$D$3:$D$49, IF($B$5="All Owners", "*", $B$5), Loan_Management!$L$3:$L$49, IF($F$5="All Status", "*", $F$5))), 0) -> 0 | F13: =IF(AND(OR($D$5="All Categories", $D$5=B13), D13>0), IFERROR(AVERAGEIFS(Loan_Management!$J$3:$J$49, Loan_Management!$C$3:$C$49, B13, Loan_Management!$D$3:$D$49, IF($B$5="All Owners", "*", $B$5), Loan_Management!$L$3:$L$49, IF($F$5="All Status", "*", $F$5)), 0), 0) -> 0.059428571 | G13: =IF($D$22>0, D13/$D$22, 0) -> 0.56517897
B14: Informal Loan | C14: =IF(OR($D$5="All Categories", $D$5=B14), COUNTIFS(Loan_Management!$C$3:$C$49, B14, Loan_Management!$D$3:$D$49, IF($B$5="All Owners", "*", $B$5), Loan_Management!$L$3:$L$49, IF($F$5="All Status", "*", $F$5)), 0) -> 4 | D14: =IF(OR($D$5="All Categories", $D$5=B14), SUMIFS(Loan_Management!$H$3:$H$49, Loan_Management!$C$3:$C$49, B14, Loan_Management!$D$3:$D$49, IF($B$5="All Owners", "*", $B$5), Loan_Management!$L$3:$L$49, IF($F$5="All Status", "*", $F$5)), 0) -> 320000 | E14: =IF(OR($D$5="All Categories", $D$5=B14), IF($H$5="Lump Sum View", SUMIFS(Loan_Management!$G$3:$G$49, Loan_Management!$C$3:$C$49, B14, Loan_Management!$D$3:$D$49, IF($B$5="All Owners", "*", $B$5), Loan_Management!$L$3:$L$49, IF($F$5="All Status", "*", $F$5)), SUMIFS(Loan_Management!$I$3:$I$49, Loan_Management!$C$3:$C$49, B14, Loan_Management!$D$3:$D$49, IF($B$5="All Owners", "*", $B$5), Loan_Management!$L$3:$L$49, IF($F$5="All Status", "*", $F$5))), 0) -> 0 | F14: =IF(AND(OR($D$5="All Categories", $D$5=B14), D14>0), IFERROR(AVERAGEIFS(Loan_Management!$J$3:$J$49, Loan_Management!$C$3:$C$49, B14, Loan_Management!$D$3:$D$49, IF($B$5="All Owners", "*", $B$5), Loan_Management!$L$3:$L$49, IF($F$5="All Status", "*", $F$5)), 0), 0) -> 0 | G14: =IF($D$22>0, D14/$D$22, 0) -> 0.14140521
B15: Fintech Credit | C15: =IF(OR($D$5="All Categories", $D$5=B15), COUNTIFS(Loan_Management!$C$3:$C$49, B15, Loan_Management!$D$3:$D$49, IF($B$5="All Owners", "*", $B$5), Loan_Management!$L$3:$L$49, IF($F$5="All Status", "*", $F$5)), 0) -> 1 | D15: =IF(OR($D$5="All Categories", $D$5=B15), SUMIFS(Loan_Management!$H$3:$H$49, Loan_Management!$C$3:$C$49, B15, Loan_Management!$D$3:$D$49, IF($B$5="All Owners", "*", $B$5), Loan_Management!$L$3:$L$49, IF($F$5="All Status", "*", $F$5)), 0) -> 175000 | E15: =IF(OR($D$5="All Categories", $D$5=B15), IF($H$5="Lump Sum View", SUMIFS(Loan_Management!$G$3:$G$49, Loan_Management!$C$3:$C$49, B15, Loan_Management!$D$3:$D$49, IF($B$5="All Owners", "*", $B$5), Loan_Management!$L$3:$L$49, IF($F$5="All Status", "*", $F$5)), SUMIFS(Loan_Management!$I$3:$I$49, Loan_Management!$C$3:$C$49, B15, Loan_Management!$D$3:$D$49, IF($B$5="All Owners", "*", $B$5), Loan_Management!$L$3:$L$49, IF($F$5="All Status", "*", $F$5))), 0) -> 0 | F15: =IF(AND(OR($D$5="All Categories", $D$5=B15), D15>0), IFERROR(AVERAGEIFS(Loan_Management!$J$3:$J$49, Loan_Management!$C$3:$C$49, B15, Loan_Management!$D$3:$D$49, IF($B$5="All Owners", "*", $B$5), Loan_Management!$L$3:$L$49, IF($F$5="All Status", "*", $F$5)), 0), 0) -> 0.26 | G15: =IF($D$22>0, D15/$D$22, 0) -> 0.077330977
B16: Community Loan | C16: =IF(OR($D$5="All Categories", $D$5=B16), COUNTIFS(Loan_Management!$C$3:$C$49, B16, Loan_Management!$D$3:$D$49, IF($B$5="All Owners", "*", $B$5), Loan_Management!$L$3:$L$49, IF($F$5="All Status", "*", $F$5)), 0) -> 1 | D16: =IF(OR($D$5="All Categories", $D$5=B16), SUMIFS(Loan_Management!$H$3:$H$49, Loan_Management!$C$3:$C$49, B16, Loan_Management!$D$3:$D$49, IF($B$5="All Owners", "*", $B$5), Loan_Management!$L$3:$L$49, IF($F$5="All Status", "*", $F$5)), 0) -> 150000 | E16: =IF(OR($D$5="All Categories", $D$5=B16), IF($H$5="Lump Sum View", SUMIFS(Loan_Management!$G$3:$G$49, Loan_Management!$C$3:$C$49, B16, Loan_Management!$D$3:$D$49, IF($B$5="All Owners", "*", $B$5), Loan_Management!$L$3:$L$49, IF($F$5="All Status", "*", $F$5)), SUMIFS(Loan_Management!$I$3:$I$49, Loan_Management!$C$3:$C$49, B16, Loan_Management!$D$3:$D$49, IF($B$5="All Owners", "*", $B$5), Loan_Management!$L$3:$L$49, IF($F$5="All Status", "*", $F$5))), 0) -> 0 | F16: =IF(AND(OR($D$5="All Categories", $D$5=B16), D16>0), IFERROR(AVERAGEIFS(Loan_Management!$J$3:$J$49, Loan_Management!$C$3:$C$49, B16, Loan_Management!$D$3:$D$49, IF($B$5="All Owners", "*", $B$5), Loan_Management!$L$3:$L$49, IF($F$5="All Status", "*", $F$5)), 0), 0) -> 0.36 | G16: =IF($D$22>0, D16/$D$22, 0) -> 0.066283694
B17: Credit Card | C17: =IF(OR($D$5="All Categories", $D$5=B17), COUNTIFS(Loan_Management!$C$3:$C$49, B17, Loan_Management!$D$3:$D$49, IF($B$5="All Owners", "*", $B$5), Loan_Management!$L$3:$L$49, IF($F$5="All Status", "*", $F$5)), 0) -> 3 | D17: =IF(OR($D$5="All Categories", $D$5=B17), SUMIFS(Loan_Management!$H$3:$H$49, Loan_Management!$C$3:$C$49, B17, Loan_Management!$D$3:$D$49, IF($B$5="All Owners", "*", $B$5), Loan_Management!$L$3:$L$49, IF($F$5="All Status", "*", $F$5)), 0) -> 139000 | E17: =IF(OR($D$5="All Categories", $D$5=B17), IF($H$5="Lump Sum View", SUMIFS(Loan_Management!$G$3:$G$49, Loan_Management!$C$3:$C$49, B17, Loan_Management!$D$3:$D$49, IF($B$5="All Owners", "*", $B$5), Loan_Management!$L$3:$L$49, IF($F$5="All Status", "*", $F$5)), SUMIFS(Loan_Management!$I$3:$I$49, Loan_Management!$C$3:$C$49, B17, Loan_Management!$D$3:$D$49, IF($B$5="All Owners", "*", $B$5), Loan_Management!$L$3:$L$49, IF($F$5="All Status", "*", $F$5))), 0) -> 0 | F17: =IF(AND(OR($D$5="All Categories", $D$5=B17), D17>0), IFERROR(AVERAGEIFS(Loan_Management!$J$3:$J$49, Loan_Management!$C$3:$C$49, B17, Loan_Management!$D$3:$D$49, IF($B$5="All Owners", "*", $B$5), Loan_Management!$L$3:$L$49, IF($F$5="All Status", "*", $F$5)), 0), 0) -> 0.17 | G17: =IF($D$22>0, D17/$D$22, 0) -> 0.06142289
B18: Vendor / Home | C18: =IF(OR($D$5="All Categories", $D$5=B18), COUNTIFS(Loan_Management!$C$3:$C$49, B18, Loan_Management!$D$3:$D$49, IF($B$5="All Owners", "*", $B$5), Loan_Management!$L$3:$L$49, IF($F$5="All Status", "*", $F$5)), 0) -> 2 | D18: =IF(OR($D$5="All Categories", $D$5=B18), SUMIFS(Loan_Management!$H$3:$H$49, Loan_Management!$C$3:$C$49, B18, Loan_Management!$D$3:$D$49, IF($B$5="All Owners", "*", $B$5), Loan_Management!$L$3:$L$49, IF($F$5="All Status", "*", $F$5)), 0) -> 75000 | E18: =IF(OR($D$5="All Categories", $D$5=B18), IF($H$5="Lump Sum View", SUMIFS(Loan_Management!$G$3:$G$49, Loan_Management!$C$3:$C$49, B18, Loan_Management!$D$3:$D$49, IF($B$5="All Owners", "*", $B$5), Loan_Management!$L$3:$L$49, IF($F$5="All Status", "*", $F$5)), SUMIFS(Loan_Management!$I$3:$I$49, Loan_Management!$C$3:$C$49, B18, Loan_Management!$D$3:$D$49, IF($B$5="All Owners", "*", $B$5), Loan_Management!$L$3:$L$49, IF($F$5="All Status", "*", $F$5))), 0) -> 0 | F18: =IF(AND(OR($D$5="All Categories", $D$5=B18), D18>0), IFERROR(AVERAGEIFS(Loan_Management!$J$3:$J$49, Loan_Management!$C$3:$C$49, B18, Loan_Management!$D$3:$D$49, IF($B$5="All Owners", "*", $B$5), Loan_Management!$L$3:$L$49, IF($F$5="All Status", "*", $F$5)), 0), 0) -> 0 | G18: =IF($D$22>0, D18/$D$22, 0) -> 0.033141847
B19: Chit Fund / BC | C19: =IF(OR($D$5="All Categories", $D$5=B19), COUNTIFS(Loan_Management!$C$3:$C$49, B19, Loan_Management!$D$3:$D$49, IF($B$5="All Owners", "*", $B$5), Loan_Management!$L$3:$L$49, IF($F$5="All Status", "*", $F$5)), 0) -> 1 | D19: =IF(OR($D$5="All Categories", $D$5=B19), SUMIFS(Loan_Management!$H$3:$H$49, Loan_Management!$C$3:$C$49, B19, Loan_Management!$D$3:$D$49, IF($B$5="All Owners", "*", $B$5), Loan_Management!$L$3:$L$49, IF($F$5="All Status", "*", $F$5)), 0) -> 40000 | E19: =IF(OR($D$5="All Categories", $D$5=B19), IF($H$5="Lump Sum View", SUMIFS(Loan_Management!$G$3:$G$49, Loan_Management!$C$3:$C$49, B19, Loan_Management!$D$3:$D$49, IF($B$5="All Owners", "*", $B$5), Loan_Management!$L$3:$L$49, IF($F$5="All Status", "*", $F$5)), SUMIFS(Loan_Management!$I$3:$I$49, Loan_Management!$C$3:$C$49, B19, Loan_Management!$D$3:$D$49, IF($B$5="All Owners", "*", $B$5), Loan_Management!$L$3:$L$49, IF($F$5="All Status", "*", $F$5))), 0) -> 0 | F19: =IF(AND(OR($D$5="All Categories", $D$5=B19), D19>0), IFERROR(AVERAGEIFS(Loan_Management!$J$3:$J$49, Loan_Management!$C$3:$C$49, B19, Loan_Management!$D$3:$D$49, IF($B$5="All Owners", "*", $B$5), Loan_Management!$L$3:$L$49, IF($F$5="All Status", "*", $F$5)), 0), 0) -> 0 | G19: =IF($D$22>0, D19/$D$22, 0) -> 0.017675652
B20: Secured / Jewel | C20: =IF(OR($D$5="All Categories", $D$5=B20), COUNTIFS(Loan_Management!$C$3:$C$49, B20, Loan_Management!$D$3:$D$49, IF($B$5="All Owners", "*", $B$5), Loan_Management!$L$3:$L$49, IF($F$5="All Status", "*", $F$5)), 0) -> 1 | D20: =IF(OR($D$5="All Categories", $D$5=B20), SUMIFS(Loan_Management!$H$3:$H$49, Loan_Management!$C$3:$C$49, B20, Loan_Management!$D$3:$D$49, IF($B$5="All Owners", "*", $B$5), Loan_Management!$L$3:$L$49, IF($F$5="All Status", "*", $F$5)), 0) -> 35000 | E20: =IF(OR($D$5="All Categories", $D$5=B20), IF($H$5="Lump Sum View", SUMIFS(Loan_Management!$G$3:$G$49, Loan_Management!$C$3:$C$49, B20, Loan_Management!$D$3:$D$49, IF($B$5="All Owners", "*", $B$5), Loan_Management!$L$3:$L$49, IF($F$5="All Status", "*", $F$5)), SUMIFS(Loan_Management!$I$3:$I$49, Loan_Management!$C$3:$C$49, B20, Loan_Management!$D$3:$D$49, IF($B$5="All Owners", "*", $B$5), Loan_Management!$L$3:$L$49, IF($F$5="All Status", "*", $F$5))), 0) -> 0 | F20: =IF(AND(OR($D$5="All Categories", $D$5=B20), D20>0), IFERROR(AVERAGEIFS(Loan_Management!$J$3:$J$49, Loan_Management!$C$3:$C$49, B20, Loan_Management!$D$3:$D$49, IF($B$5="All Owners", "*", $B$5), Loan_Management!$L$3:$L$49, IF($F$5="All Status", "*", $F$5)), 0), 0) -> 0.36 | G20: =IF($D$22>0, D20/$D$22, 0) -> 0.015466195
B21: Family & Other | C21: =IF(OR($D$5="All Categories", $D$5=B21), COUNTIFS(Loan_Management!$C$3:$C$49, "Family Loan", Loan_Management!$D$3:$D$49, IF($B$5="All Owners", "*", $B$5), Loan_Management!$L$3:$L$49, IF($F$5="All Status", "*", $F$5)) + COUNTIFS(Loan_Management!$C$3:$C$49, "Contingency", Loan_Management!$D$3:$D$49, IF($B$5="All Owners", "*", $B$5), Loan_Management!$L$3:$L$49, IF($F$5="All Status", "*", $F$5)) + COUNTIFS(Loan_Management!$C$3:$C$49, "Household", Loan_Management!$D$3:$D$49, IF($B$5="All Owners", "*", $B$5), Loan_Management!$L$3:$L$49, IF($F$5="All Status", "*", $F$5)) + COUNTIFS(Loan_Management!$C$3:$C$49, "Other", Loan_Management!$D$3:$D$49, IF($B$5="All Owners", "*", $B$5), Loan_Management!$L$3:$L$49, IF($F$5="All Status", "*", $F$5)), 0) -> 3 | D21: =IF(OR($D$5="All Categories", $D$5=B21), SUMIFS(Loan_Management!$H$3:$H$49, Loan_Management!$C$3:$C$49, "Family Loan", Loan_Management!$D$3:$D$49, IF($B$5="All Owners", "*", $B$5), Loan_Management!$L$3:$L$49, IF($F$5="All Status", "*", $F$5)) + SUMIFS(Loan_Management!$H$3:$H$49, Loan_Management!$C$3:$C$49, "Contingency", Loan_Management!$D$3:$D$49, IF($B$5="All Owners", "*", $B$5), Loan_Management!$L$3:$L$49, IF($F$5="All Status", "*", $F$5)) + SUMIFS(Loan_Management!$H$3:$H$49, Loan_Management!$C$3:$C$49, "Household", Loan_Management!$D$3:$D$49, IF($B$5="All Owners", "*", $B$5), Loan_Management!$L$3:$L$49, IF($F$5="All Status", "*", $F$5)) + SUMIFS(Loan_Management!$H$3:$H$49, Loan_Management!$C$3:$C$49, "Other", Loan_Management!$D$3:$D$49, IF($B$5="All Owners", "*", $B$5), Loan_Management!$L$3:$L$49, IF($F$5="All Status", "*", $F$5)), 0) -> 50000 | E21: =IF(OR($D$5="All Categories", $D$5=B21), IF($H$5="Lump Sum View", SUMIFS(Loan_Management!$G$3:$G$49, Loan_Management!$C$3:$C$49, "Family Loan", Loan_Management!$D$3:$D$49, IF($B$5="All Owners", "*", $B$5), Loan_Management!$L$3:$L$49, IF($F$5="All Status", "*", $F$5)) + SUMIFS(Loan_Management!$G$3:$G$49, Loan_Management!$C$3:$C$49, "Contingency", Loan_Management!$D$3:$D$49, IF($B$5="All Owners", "*", $B$5), Loan_Management!$L$3:$L$49, IF($F$5="All Status", "*", $F$5)) + SUMIFS(Loan_Management!$G$3:$G$49, Loan_Management!$C$3:$C$49, "Household", Loan_Management!$D$3:$D$49, IF($B$5="All Owners", "*", $B$5), Loan_Management!$L$3:$L$49, IF($F$5="All Status", "*", $F$5)) + SUMIFS(Loan_Management!$G$3:$G$49, Loan_Management!$C$3:$C$49, "Other", Loan_Management!$D$3:$D$49, IF($B$5="All Owners", "*", $B$5), Loan_Management!$L$3:$L$49, IF($F$5="All Status", "*", $F$5)), SUMIFS(Loan_Management!$I$3:$I$49, Loan_Management!$C$3:$C$49, "Family Loan", Loan_Management!$D$3:$D$49, IF($B$5="All Owners", "*", $B$5), Loan_Management!$L$3:$L$49, IF($F$5="All Status", "*", $F$5)) + SUMIFS(Loan_Management!$I$3:$I$49, Loan_Management!$C$3:$C$49, "Contingency", Loan_Management!$D$3:$D$49, IF($B$5="All Owners", "*", $B$5), Loan_Management!$L$3:$L$49, IF($F$5="All Status", "*", $F$5)) + SUMIFS(Loan_Management!$I$3:$I$49, Loan_Management!$C$3:$C$49, "Household", Loan_Management!$D$3:$D$49, IF($B$5="All Owners", "*", $B$5), Loan_Management!$L$3:$L$49, IF($F$5="All Status", "*", $F$5)) + SUMIFS(Loan_Management!$I$3:$I$49, Loan_Management!$C$3:$C$49, "Other", Loan_Management!$D$3:$D$49, IF($B$5="All Owners", "*", $B$5), Loan_Management!$L$3:$L$49, IF($F$5="All Status", "*", $F$5))), 0) -> 0 | F21: 0 | G21: =IF($D$22>0, D21/$D$22, 0) -> 0.022094565
B22: TOTAL PORTFOLIO | C22: =SUM(C13:C21) -> 23 | D22: =SUM(D13:D21) -> 2263000 | E22: =SUM(E13:E21) -> 0 | F22: =IF(D22>0, SUMPRODUCT(D13:D21, F13:F21)/D22, 0) -> 0.093565684 | G22: =SUM(G13:G21) -> 1

Sheet Monthly_Repayments
B1: 💳 Monthly Debt Repayment & Outflow Ledger
B4: TOTAL PAYMENTS REPAID | D4: CURRENT MONTH OUTFLOW | F4: LUMP SUM PREPAYMENTS | H4: AVG PAYMENT SIZE
B5: =SUM(G9:G100) -> 0 | D5: =SUMIFS(G9:G100, C9:C100, ">="&DATE(YEAR(TODAY()), MONTH(TODAY()), 1), C9:C100, "<="&EOMONTH(TODAY(), 0)) -> 0 | F5: =SUMIF(F9:F100, "Lump Sum", G9:G100) -> 0 | H5: =IFERROR(AVERAGEIF(G9:G100, ">0"), 0) -> 0
B6: Cumulative logged outflow | D6: October 2026 cycle | F6: Principal reductions | H6: Average per transaction
B8: Payment ID | C8: Payment Date | D8: Liability / Loan Name | E8: Portfolio Owner | F8: Payment Type | G8: Amount Paid (₹) | H8: Payment Status | I8: Notes & Remarks
B9: PAY-2026-001 | C9: 46300 | D9: Slice | E9: Shahil | F9: Monthly EMI | G9: {=IF(OR(D9="", F9=""), "", IFERROR(_xludf.IFS(F9="Monthly EMI", _xlfn.XLOOKUP(D9, Loan_Management!$B$3:$B$25, Loan_Management!$I$3:$I$25, 0), F9="Full Settlement", _xlfn.XLOOKUP(D9, Loan_Management!$B$3:$B$25, Loan_Management!$F$3:$F$25, 0), F9="Interest Only", _xlfn.XLOOKUP(D9, Loan_Management!$B$3:$B$25, Loan_Management!$I$3:$I$25, 0), F9="Lump Sum", 10000, TRUE, 0), 0))} -> 0 | H9: Pending | I9: Automated EMI debit
B10: PAY-2026-002 | C10: 46300 | D10: ICICI Credit Card | E10: Shahil | F10: Monthly EMI | G10: {=IF(OR(D10="", F10=""), "", IFERROR(_xludf.IFS(F10="Monthly EMI", _xlfn.XLOOKUP(D10, Loan_Management!$B$3:$B$25, Loan_Management!$I$3:$I$25, 0), F10="Full Settlement", _xlfn.XLOOKUP(D10, Loan_Management!$B$3:$B$25, Loan_Management!$F$3:$F$25, 0), F10="Interest Only", _xlfn.XLOOKUP(D10, Loan_Management!$B$3:$B$25, Loan_Management!$I$3:$I$25, 0), F10="Lump Sum", 10000, TRUE, 0), 0))} -> 0 | H10: Pending | I10: Card bill statement clearance
B11: PAY-2026-003 | C11: 46300 | D11: Abba BC | E11: Abba | F11: Monthly EMI | G11: {=IF(OR(D11="", F11=""), "", IFERROR(_xludf.IFS(F11="Monthly EMI", _xlfn.XLOOKUP(D11, Loan_Management!$B$3:$B$25, Loan_Management!$I$3:$I$25, 0), F11="Full Settlement", _xlfn.XLOOKUP(D11, Loan_Management!$B$3:$B$25, Loan_Management!$F$3:$F$25, 0), F11="Interest Only", _xlfn.XLOOKUP(D11, Loan_Management!$B$3:$B$25, Loan_Management!$I$3:$I$25, 0), F11="Lump Sum", 10000, TRUE, 0), 0))} -> 0 | H11: Pending | I11: BC committee monthly instalment
B12: PAY-2026-004 | C12: 46315 | D12: Mahila Samiti | E12: Ammi | F12: Interest Only | G12: {=IF(OR(D12="", F12=""), "", IFERROR(_xludf.IFS(F12="Monthly EMI", _xlfn.XLOOKUP(D12, Loan_Management!$B$3:$B$25, Loan_Management!$I$3:$I$25, 0), F12="Full Settlement", _xlfn.XLOOKUP(D12, Loan_Management!$B$3:$B$25, Loan_Management!$F$3:$F$25, 0), F12="Interest Only", _xlfn.XLOOKUP(D12, Loan_Management!$B$3:$B$25, Loan_Management!$I$3:$I$25, 0), F12="Lump Sum", 10000, TRUE, 0), 0))} -> 0 | H12: Pending | I12: Monthly loan interest servicing
B13: PAY-2026-005 | C13: 46305 | D13: Riyasat (2k) | E13: Mukhtar | F13: Monthly EMI | G13: {=IF(OR(D13="", F13=""), "", IFERROR(_xludf.IFS(F13="Monthly EMI", _xlfn.XLOOKUP(D13, Loan_Management!$B$3:$B$25, Loan_Management!$I$3:$I$25, 0), F13="Full Settlement", _xlfn.XLOOKUP(D13, Loan_Management!$B$3:$B$25, Loan_Management!$F$3:$F$25, 0), F13="Interest Only", _xlfn.XLOOKUP(D13, Loan_Management!$B$3:$B$25, Loan_Management!$I$3:$I$25, 0), F13="Lump Sum", 10000, TRUE, 0), 0))} -> 0 | H13: Pending | I13: Monthly scheduled repayment
B14: PAY-2026-006 | C14: 46331 | D14: Jewar (Gold Loan) | E14: Ammi | F14: Lump Sum | G14: {=IF(OR(D14="", F14=""), "", IFERROR(_xludf.IFS(F14="Monthly EMI", _xlfn.XLOOKUP(D14, Loan_Management!$B$3:$B$25, Loan_Management!$I$3:$I$25, 0), F14="Full Settlement", _xlfn.XLOOKUP(D14, Loan_Management!$B$3:$B$25, Loan_Management!$F$3:$F$25, 0), F14="Interest Only", _xlfn.XLOOKUP(D14, Loan_Management!$B$3:$B$25, Loan_Management!$I$3:$I$25, 0), F14="Lump Sum", 10000, TRUE, 0), 0))} -> 0 | H14: Pending | I14: Partial principal lump sum payment
B15: PAY-2026-007 | C15: 46300 | D15: Piramal Capital | E15: Shahil | F15: Monthly EMI | G15: {=IF(OR(D15="", F15=""), "", IFERROR(_xludf.IFS(F15="Monthly EMI", _xlfn.XLOOKUP(D15, Loan_Management!$B$3:$B$25, Loan_Management!$I$3:$I$25, 0), F15="Full Settlement", _xlfn.XLOOKUP(D15, Loan_Management!$B$3:$B$25, Loan_Management!$F$3:$F$25, 0), F15="Interest Only", _xlfn.XLOOKUP(D15, Loan_Management!$B$3:$B$25, Loan_Management!$I$3:$I$25, 0), F15="Lump Sum", 10000, TRUE, 0), 0))} -> 0 | H15: Pending | I15: NBFC loan regular EMI
B16: PAY-2026-008 | C16: 46315 | D16: IDFC First Bank | E16: Ammi | F16: Monthly EMI | G16: {=IF(OR(D16="", F16=""), "", IFERROR(_xludf.IFS(F16="Monthly EMI", _xlfn.XLOOKUP(D16, Loan_Management!$B$3:$B$25, Loan_Management!$I$3:$I$25, 0), F16="Full Settlement", _xlfn.XLOOKUP(D16, Loan_Management!$B$3:$B$25, Loan_Management!$F$3:$F$25, 0), F16="Interest Only", _xlfn.XLOOKUP(D16, Loan_Management!$B$3:$B$25, Loan_Management!$I$3:$I$25, 0), F16="Lump Sum", 10000, TRUE, 0), 0))} -> 0 | H16: Pending | I16: Personal loan monthly schedule
B17: PAY-2026-009 | C17: 46300 | D17: Cred 1 | E17: Shahil | F17: Monthly EMI | G17: {=IF(OR(D17="", F17=""), "", IFERROR(_xludf.IFS(F17="Monthly EMI", _xlfn.XLOOKUP(D17, Loan_Management!$B$3:$B$25, Loan_Management!$I$3:$I$25, 0), F17="Full Settlement", _xlfn.XLOOKUP(D17, Loan_Management!$B$3:$B$25, Loan_Management!$F$3:$F$25, 0), F17="Interest Only", _xlfn.XLOOKUP(D17, Loan_Management!$B$3:$B$25, Loan_Management!$I$3:$I$25, 0), F17="Lump Sum", 10000, TRUE, 0), 0))} -> 0 | H17: Pending | I17: Credit line billing settlement
B18: PAY-2026-010 | C18: 46300 | D18: Cred 2 | E18: Shahil | F18: Monthly EMI | G18: {=IF(OR(D18="", F18=""), "", IFERROR(_xludf.IFS(F18="Monthly EMI", _xlfn.XLOOKUP(D18, Loan_Management!$B$3:$B$25, Loan_Management!$I$3:$I$25, 0), F18="Full Settlement", _xlfn.XLOOKUP(D18, Loan_Management!$B$3:$B$25, Loan_Management!$F$3:$F$25, 0), F18="Interest Only", _xlfn.XLOOKUP(D18, Loan_Management!$B$3:$B$25, Loan_Management!$I$3:$I$25, 0), F18="Lump Sum", 10000, TRUE, 0), 0))} -> 0 | H18: Pending | I18: Credit line installment paid
B19: PAY-2026-011 | G19: {=IF(OR(D19="", F19=""), "", IFERROR(_xludf.IFS(F19="Monthly EMI", _xlfn.XLOOKUP(D19, Loan_Management!$B$3:$B$25, Loan_Management!$I$3:$I$25, 0), F19="Full Settlement", _xlfn.XLOOKUP(D19, Loan_Management!$B$3:$B$25, Loan_Management!$F$3:$F$25, 0), F19="Interest Only", _xlfn.XLOOKUP(D19, Loan_Management!$B$3:$B$25, Loan_Management!$I$3:$I$25, 0), F19="Lump Sum", 10000, TRUE, 0), 0))}
B20: PAY-2026-012 | G20: {=IF(OR(D20="", F20=""), "", IFERROR(_xludf.IFS(F20="Monthly EMI", _xlfn.XLOOKUP(D20, Loan_Management!$B$3:$B$25, Loan_Management!$I$3:$I$25, 0), F20="Full Settlement", _xlfn.XLOOKUP(D20, Loan_Management!$B$3:$B$25, Loan_Management!$F$3:$F$25, 0), F20="Interest Only", _xlfn.XLOOKUP(D20, Loan_Management!$B$3:$B$25, Loan_Management!$I$3:$I$25, 0), F20="Lump Sum", 10000, TRUE, 0), 0))}
B21: PAY-2026-013 | G21: {=IF(OR(D21="", F21=""), "", IFERROR(_xludf.IFS(F21="Monthly EMI", _xlfn.XLOOKUP(D21, Loan_Management!$B$3:$B$25, Loan_Management!$I$3:$I$25, 0), F21="Full Settlement", _xlfn.XLOOKUP(D21, Loan_Management!$B$3:$B$25, Loan_Management!$F$3:$F$25, 0), F21="Interest Only", _xlfn.XLOOKUP(D21, Loan_Management!$B$3:$B$25, Loan_Management!$I$3:$I$25, 0), F21="Lump Sum", 10000, TRUE, 0), 0))}
B22: PAY-2026-014 | G22: {=IF(OR(D22="", F22=""), "", IFERROR(_xludf.IFS(F22="Monthly EMI", _xlfn.XLOOKUP(D22, Loan_Management!$B$3:$B$25, Loan_Management!$I$3:$I$25, 0), F22="Full Settlement", _xlfn.XLOOKUP(D22, Loan_Management!$B$3:$B$25, Loan_Management!$F$3:$F$25, 0), F22="Interest Only", _xlfn.XLOOKUP(D22, Loan_Management!$B$3:$B$25, Loan_Management!$I$3:$I$25, 0), F22="Lump Sum", 10000, TRUE, 0), 0))}
B23: PAY-2026-015 | G23: {=IF(OR(D23="", F23=""), "", IFERROR(_xludf.IFS(F23="Monthly EMI", _xlfn.XLOOKUP(D23, Loan_Management!$B$3:$B$25, Loan_Management!$I$3:$I$25, 0), F23="Full Settlement", _xlfn.XLOOKUP(D23, Loan_Management!$B$3:$B$25, Loan_Management!$F$3:$F$25, 0), F23="Interest Only", _xlfn.XLOOKUP(D23, Loan_Management!$B$3:$B$25, Loan_Management!$I$3:$I$25, 0), F23="Lump Sum", 10000, TRUE, 0), 0))}
